Peer will receive following PB traceback:
Unhandled Error
Traceback (most recent call last):
  File "/usr/lib/python2.7/dist-packages/twisted/spread/banana.py", line 153, in gotItem
    self.callExpressionReceived(item)
  File "/usr/lib/python2.7/dist-packages/twisted/spread/banana.py", line 116, in callExpressionReceived
    self.expressionReceived(obj)
  File "/usr/lib/python2.7/dist-packages/twisted/spread/pb.py", line 565, in expressionReceived
    method(*sexp[1:])
  File "/usr/lib/python2.7/dist-packages/twisted/spread/pb.py", line 877, in proto_message
    self._recvMessage(self.localObjectForID, requestID, objectID, message, answerRequired, netArgs, netKw)
--- <exception caught here> ---
  File "/usr/lib/python2.7/dist-packages/twisted/spread/pb.py", line 891, in _recvMessage
    netResult = object.remoteMessageReceived(self, message, netArgs, netKw)
  File "/usr/lib/python2.7/dist-packages/twisted/spread/flavors.py", line 114, in remoteMessageReceived
    state = method(*args, **kw)
  File "/home/francesco/Scrivania/TesinaSSD/workingCopy/node.py", line 182, in remote_passNode
    self.incomingConnection(callerNode)
  File "/home/francesco/Scrivania/TesinaSSD/workingCopy/node.py", line 131, in incomingConnection
    str(callerNode.address)+" "+str(callerNode.port))
exceptions.AttributeError: 'tuple' object has no attribute 'user_id'
Peer will receive following PB traceback:
Unhandled Error
Traceback (most recent call last):
  File "/usr/lib/python2.7/dist-packages/twisted/spread/banana.py", line 153, in gotItem
    self.callExpressionReceived(item)
  File "/usr/lib/python2.7/dist-packages/twisted/spread/banana.py", line 116, in callExpressionReceived
    self.expressionReceived(obj)
  File "/usr/lib/python2.7/dist-packages/twisted/spread/pb.py", line 565, in expressionReceived
    method(*sexp[1:])
  File "/usr/lib/python2.7/dist-packages/twisted/spread/pb.py", line 877, in proto_message
    self._recvMessage(self.localObjectForID, requestID, objectID, message, answerRequired, netArgs, netKw)
--- <exception caught here> ---
  File "/usr/lib/python2.7/dist-packages/twisted/spread/pb.py", line 891, in _recvMessage
    netResult = object.remoteMessageReceived(self, message, netArgs, netKw)
  File "/usr/lib/python2.7/dist-packages/twisted/spread/flavors.py", line 114, in remoteMessageReceived
    state = method(*args, **kw)
  File "/home/francesco/Scrivania/TesinaSSD/workingCopy/node.py", line 182, in remote_passNode
    self.incomingConnection(callerNode)
  File "/home/francesco/Scrivania/TesinaSSD/workingCopy/node.py", line 131, in incomingConnection
    str(callerNode.address)+" "+str(callerNode.port))
exceptions.AttributeError: 'tuple' object has no attribute 'user_id'
Peer will receive following PB traceback:
Unhandled Error
Traceback (most recent call last):
  File "/usr/lib/python2.7/dist-packages/twisted/spread/banana.py", line 153, in gotItem
    self.callExpressionReceived(item)
  File "/usr/lib/python2.7/dist-packages/twisted/spread/banana.py", line 116, in callExpressionReceived
    self.expressionReceived(obj)
  File "/usr/lib/python2.7/dist-packages/twisted/spread/pb.py", line 565, in expressionReceived
    method(*sexp[1:])
  File "/usr/lib/python2.7/dist-packages/twisted/spread/pb.py", line 877, in proto_message
    self._recvMessage(self.localObjectForID, requestID, objectID, message, answerRequired, netArgs, netKw)
--- <exception caught here> ---
  File "/usr/lib/python2.7/dist-packages/twisted/spread/pb.py", line 891, in _recvMessage
    netResult = object.remoteMessageReceived(self, message, netArgs, netKw)
  File "/usr/lib/python2.7/dist-packages/twisted/spread/flavors.py", line 114, in remoteMessageReceived
    state = method(*args, **kw)
  File "/home/francesco/Scrivania/TesinaSSD/workingCopy/node.py", line 182, in remote_passNode
    self.incomingConnection(callerNode)
  File "/home/francesco/Scrivania/TesinaSSD/workingCopy/node.py", line 131, in incomingConnection
    str(callerNode.address)+" "+str(callerNode.port))
exceptions.AttributeError: 'tuple' object has no attribute 'user_id'
